Workbook

Sheet 赋能直播业务
B1: 所属场景 | C1: 环节 | D1: 商用目标功能 | E1: 商用细分需求 | F1: 商用必备等级 | G1: 闻道作业现状 | H1: 是否满足商用目标 | I1: 后续计划 | J1: 计划完成时间 | K1: 状态
A2: 1 | B2: =VLOOKUP(A:A,'全量进度管理'!A:L,2,FALSE) -> 校本资源建设与管理 | C2: =VLOOKUP(A:A,'全量进度管理'!A:L,3,FALSE) -> 校本资源建设 | D2: =VLOOKUP(A:A,'全量进度管理'!A:L,4,FALSE) -> 校本资源建设与管理闭环 | E2: =VLOOKUP(A:A,'全量进度管理'!A:L,5,FALSE) -> 题单资源的便捷自主建设 | F2: 低 | G2: =VLOOKUP(A:A,'全量进度管理'!A:L,8,FALSE) -> 支持教师自主建设题单；但欠缺一定的便捷性 | H2: =VLOOKUP(A:A,'全量进度管理'!A:L,9,FALSE) -> 基本满足 | I2: =VLOOKUP(A:A,'全量进度管理'!A:L,10,FALSE) -> 持续优化便捷性和AI识别准确性 | J2: =VLOOKUP(A:A,'全量进度管理'!A:L,11,FALSE) -> 46234 | K2: =VLOOKUP(A:A,'全量进度管理'!A:L,12,FALSE) -> 开发中
A3: 3 | E3: =VLOOKUP(A:A,'全量进度管理'!A:L,5,FALSE) -> 校本资源数据看板 | F3: =VLOOKUP(A:A,'全量进度管理'!A:L,6,FALSE) -> 低 | G3: =VLOOKUP(A:A,'全量进度管理'!A:L,8,FALSE) -> 无 | H3: =VLOOKUP(A:A,'全量进度管理'!A:L,9,FALSE) -> 完全不满足 | K3: =VLOOKUP(A:A,'全量进度管理'!A:L,12,FALSE) -> 待排期
A4: 5 | B4: =VLOOKUP(A:A,'全量进度管理'!A:L,2,FALSE) -> 日常作业与练习 | C4: =VLOOKUP(A:A,'全量进度管理'!A:L,3,FALSE) -> 组卷 | D4: =VLOOKUP(A:A,'全量进度管理'!A:L,4,FALSE) -> 多来源兼容 | E4: =VLOOKUP(A:A,'全量进度管理'!A:L,5,FALSE) -> 平台内题单资源使用 | F4: =VLOOKUP(A:A,'全量进度管理'!A:L,6,FALSE) -> 高 | G4: =VLOOKUP(A:A,'全量进度管理'!A:L,8,FALSE) -> 支持用户直接使用平台内题单 | H4: =VLOOKUP(A:A,'全量进度管理'!A:L,9,FALSE) -> 完全满足
A5: 8 | E5: =VLOOKUP(A:A,'全量进度管理'!A:L,5,FALSE) -> 基于学情的智能组卷 | F5: =VLOOKUP(A:A,'全量进度管理'!A:L,6,FALSE) -> 低 | G5: =VLOOKUP(A:A,'全量进度管理'!A:L,8,FALSE) -> 无 | H5: =VLOOKUP(A:A,'全量进度管理'!A:L,9,FALSE) -> 完全不满足 | I5: =VLOOKUP(A:A,'全量进度管理'!A:L,10,FALSE) -> 支持教师基于学情进行智能组卷 | K5: =VLOOKUP(A:A,'全量进度管理'!A:L,12,FALSE) -> 待排期
A6: 9 | C6: =VLOOKUP(A:A,'全量进度管理'!A:L,3,FALSE) -> 生成答题卡 | D6: =VLOOKUP(A:A,'全量进度管理'!A:L,4,FALSE) -> 支持常见纸张 | E6: =VLOOKUP(A:A,'全量进度管理'!A:L,5,FALSE) -> 支持学校常用纸张 | F6: =VLOOKUP(A:A,'全量进度管理'!A:L,6,FALSE) -> 高 | G6: =VLOOKUP(A:A,'全量进度管理'!A:L,8,FALSE) -> 支持A3、A4、B4、8K常用纸张大小 | H6: =VLOOKUP(A:A,'全量进度管理'!A:L,9,FALSE) -> 完全满足
A7: 10 | E7: =VLOOKUP(A:A,'全量进度管理'!A:L,5,FALSE) -> 支持先制卡后制题 | F7: =VLOOKUP(A:A,'全量进度管理'!A:L,6,FALSE) -> 低 | G7: =VLOOKUP(A:A,'全量进度管理'!A:L,8,FALSE) -> 无 | H7: =VLOOKUP(A:A,'全量进度管理'!A:L,9,FALSE) -> 完全不满足 | I7: =VLOOKUP(A:A,'全量进度管理'!A:L,10,FALSE) -> 考试场景拓展后兼容 | K7: =VLOOKUP(A:A,'全量进度管理'!A:L,12,FALSE) -> 待排期
A8: 11 | C8: =VLOOKUP(A:A,'全量进度管理'!A:L,3,FALSE) -> 扫描 | D8: =VLOOKUP(A:A,'全量进度管理'!A:L,4,FALSE) -> 多设备兼容 | E8: =VLOOKUP(A:A,'全量进度管理'!A:L,5,FALSE) -> 支持主流品牌扫描仪的直连 | F8: =VLOOKUP(A:A,'全量进度管理'!A:L,6,FALSE) -> 中 | G8: =VLOOKUP(A:A,'全量进度管理'!A:L,8,FALSE) -> 理论上基本支持，但部分机器可能存在兼容问题，需具体型号具体观察和解决 | H8: =VLOOKUP(A:A,'全量进度管理'!A:L,9,FALSE) -> 基本满足 | I8: =VLOOKUP(A:A,'全量进度管理'!A:L,10,FALSE) -> 新增新设备使用时，提前调试，及时发现问题解决问题
A9: 12 | D9: =VLOOKUP(A:A,'全量进度管理'!A:L,4,FALSE) -> 一键式便捷扫描 | E9: =VLOOKUP(A:A,'全量进度管理'!A:L,5,FALSE) -> 扫描开始后自动进行，无额外人工动作 | F9: =VLOOKUP(A:A,'全量进度管理'!A:L,6,FALSE) -> 中 | G9: =VLOOKUP(A:A,'全量进度管理'!A:L,8,FALSE) -> 支持一键快速扫描 | H9: =VLOOKUP(A:A,'全量进度管理'!A:L,9,FALSE) -> 完全满足
A10: 13 | C10: =VLOOKUP(A:A,'全量进度管理'!A:L,3,FALSE) -> 异常处理 | D10: =VLOOKUP(A:A,'全量进度管理'!A:L,4,FALSE) -> 异常数据尽量少 | E10: =VLOOKUP(A:A,'全量进度管理'!A:L,5,FALSE) -> 有规律的异常可以系统自动处理 | F10: =VLOOKUP(A:A,'全量进度管理'!A:L,6,FALSE) -> 非必须 | G10: =VLOOKUP(A:A,'全量进度管理'!A:L,8,FALSE) -> 部分能总结出规律的异常已加入系统规则，自动处理；但仍需持续观察异常数据， | H10: =VLOOKUP(A:A,'全量进度管理'!A:L,9,FALSE) -> 完全满足
A11: 14 | D11: =VLOOKUP(A:A,'全量进度管理'!A:L,4,FALSE) -> 支持手动处理各类异常 | E11: =VLOOKUP(A:A,'全量进度管理'!A:L,5,FALSE) -> 教师能手动处理各类异常 | F11: =VLOOKUP(A:A,'全量进度管理'!A:L,6,FALSE) -> 高 | G11: =VLOOKUP(A:A,'全量进度管理'!A:L,8,FALSE) -> 支持教师、运营处理每次扫描数据的异常内容 | H11: =VLOOKUP(A:A,'全量进度管理'!A:L,9,FALSE) -> 完全满足
A12: 15 | E12: =VLOOKUP(A:A,'全量进度管理'!A:L,5,FALSE) -> 操作便捷 | F12: =VLOOKUP(A:A,'全量进度管理'!A:L,6,FALSE) -> 中 | G12: =VLOOKUP(A:A,'全量进度管理'!A:L,8,FALSE) -> 交互复杂，存在一定的优化空间 | H12: =VLOOKUP(A:A,'全量进度管理'!A:L,9,FALSE) -> 基本满足 | K12: =VLOOKUP(A:A,'全量进度管理'!A:L,12,FALSE) -> 待排期
A13: 16 | C13: =VLOOKUP(A:A,'全量进度管理'!A:L,3,FALSE) -> 识别与批改 | D13: =VLOOKUP(A:A,'全量进度管理'!A:L,4,FALSE) -> 识别准确率高 | E13: =VLOOKUP(A:A,'全量进度管理'!A:L,5,FALSE) -> AI自动识别客观题和分数准确率>99.5% | F13: =VLOOKUP(A:A,'全量进度管理'!A:L,6,FALSE) -> 高 | G13: =VLOOKUP(A:A,'全量进度管理'!A:L,8,FALSE) -> 准确率稳定在99.5%~99.8%，处于行业中上水平 | H13: =VLOOKUP(A:A,'全量进度管理'!A:L,9,FALSE) -> 完全满足
A14: 17 | D14: =VLOOKUP(A:A,'全量进度管理'!A:L,4,FALSE) -> 识别结果校验 | E14: =VLOOKUP(A:A,'全量进度管理'!A:L,5,FALSE) -> 支持快速检验采集结果的准确性 | F14: =VLOOKUP(A:A,'全量进度管理'!A:L,6,FALSE) -> 中 | G14: =VLOOKUP(A:A,'全量进度管理'!A:L,8,FALSE) -> 支持集中呈现可能识别有误的数据，支持教师手动修正 | H14: =VLOOKUP(A:A,'全量进度管理'!A:L,9,FALSE) -> 完全满足
A15: 18 | D15: =VLOOKUP(A:A,'全量进度管理'!A:L,4,FALSE) -> AI自动批阅 | E15: =VLOOKUP(A:A,'全量进度管理'!A:L,5,FALSE) -> 作文类 | F15: =VLOOKUP(A:A,'全量进度管理'!A:L,6,FALSE) -> 低 | G15: =VLOOKUP(A:A,'全量进度管理'!A:L,8,FALSE) -> 支持英语作文批阅，但是语文作文还欠缺 | H15: =VLOOKUP(A:A,'全量进度管理'!A:L,9,FALSE) -> 基本满足 | I15: =VLOOKUP(A:A,'全量进度管理'!A:L,10,FALSE) -> 支持语文作文 | K15: =VLOOKUP(A:A,'全量进度管理'!A:L,12,FALSE) -> 待排期
A16: 19 | E16: =VLOOKUP(A:A,'全量进度管理'!A:L,5,FALSE) -> 填空题 | F16: =VLOOKUP(A:A,'全量进度管理'!A:L,6,FALSE) -> 中 | G16: =VLOOKUP(A:A,'全量进度管理'!A:L,8,FALSE) -> 无 | H16: =VLOOKUP(A:A,'全量进度管理'!A:L,9,FALSE) -> 完全不满足 | I16: =VLOOKUP(A:A,'全量进度管理'!A:L,10,FALSE) -> 优先实现英语填空题的自动批阅 | J16: =VLOOKUP(A:A,'全量进度管理'!A:L,11,FALSE) -> 46265 | K16: =VLOOKUP(A:A,'全量进度管理'!A:L,12,FALSE) -> 已排期
A17: 20 | E17: =VLOOKUP(A:A,'全量进度管理'!A:L,5,FALSE) -> 主观题 | F17: =VLOOKUP(A:A,'全量进度管理'!A:L,6,FALSE) -> 中 | G17: =VLOOKUP(A:A,'全量进度管理'!A:L,8,FALSE) -> 无 | H17: =VLOOKUP(A:A,'全量进度管理'!A:L,9,FALSE) -> 完全不满足
A18: 21 | E18: =VLOOKUP(A:A,'全量进度管理'!A:L,5,FALSE) -> 留痕批阅 | F18: =VLOOKUP(A:A,'全量进度管理'!A:L,6,FALSE) -> 中 | G18: =VLOOKUP(A:A,'全量进度管理'!A:L,8,FALSE) -> 无 | H18: =VLOOKUP(A:A,'全量进度管理'!A:L,9,FALSE) -> 完全不满足
A19: 22 | D19: =VLOOKUP(A:A,'全量进度管理'!A:L,4,FALSE) -> 在线批阅 | E19: =VLOOKUP(A:A,'全量进度管理'!A:L,5,FALSE) -> 支持教师在线批阅 | F19: =VLOOKUP(A:A,'全量进度管理'!A:L,6,FALSE) -> 低 | G19: =VLOOKUP(A:A,'全量进度管理'!A:L,8,FALSE) -> 支持教师在线批阅题单 | H19: =VLOOKUP(A:A,'全量进度管理'!A:L,9,FALSE) -> 完全满足
A20: 23 | C20: =VLOOKUP(A:A,'全量进度管理'!A:L,3,FALSE) -> 数据查看与应用 | D20: =VLOOKUP(A:A,'全量进度管理'!A:L,4,FALSE) -> 教师查看数据 | E20: =VLOOKUP(A:A,'全量进度管理'!A:L,5,FALSE) -> 教师查看单次测验数据 | F20: =VLOOKUP(A:A,'全量进度管理'!A:L,6,FALSE) -> 高 | G20: =VLOOKUP(A:A,'全量进度管理'!A:L,8,FALSE) -> 支持教师查看单次测验数据 | H20: =VLOOKUP(A:A,'全量进度管理'!A:L,9,FALSE) -> 完全满足
A21: 24 | E21: =VLOOKUP(A:A,'全量进度管理'!A:L,5,FALSE) -> 教师查看阶段数据 | F21: =VLOOKUP(A:A,'全量进度管理'!A:L,6,FALSE) -> 高 | G21: =VLOOKUP(A:A,'全量进度管理'!A:L,8,FALSE) -> 支持教师查看阶段数据，但是老版本；与当前业务的融合性不够 | H21: =VLOOKUP(A:A,'全量进度管理'!A:L,9,FALSE) -> 基本满足 | I21: =VLOOKUP(A:A,'全量进度管理'!A:L,10,FALSE) -> 升级阶段学情 | K21: =VLOOKUP(A:A,'全量进度管理'!A:L,12,FALSE) -> 待排期
A22: 25 | E22: =VLOOKUP(A:A,'全量进度管理'!A:L,5,FALSE) -> 不同角色校管查看数据 | F22: =VLOOKUP(A:A,'全量进度管理'!A:L,6,FALSE) -> 高 | G22: =VLOOKUP(A:A,'全量进度管理'!A:L,8,FALSE) -> 支持不同角色查看年级数据 | H22: =VLOOKUP(A:A,'全量进度管理'!A:L,9,FALSE) -> 完全满足 | I22: =VLOOKUP(A:A,'全量进度管理'!A:L,10,FALSE) -> 由于三方系统原因，导致权限会有部分放大，但总体不影响使用；后续优化权限 | K22: =VLOOKUP(A:A,'全量进度管理'!A:L,12,FALSE) -> 待排期
A23: 26 | D23: =VLOOKUP(A:A,'全量进度管理'!A:L,4,FALSE) -> 教师讲评 | E23: =VLOOKUP(A:A,'全量进度管理'!A:L,5,FALSE) -> 支持教师基于题单进行讲评 | F23: =VLOOKUP(A:A,'全量进度管理'!A:L,6,FALSE) -> 中 | G23: =VLOOKUP(A:A,'全量进度管理'!A:L,8,FALSE) -> 支持讲评、导出讲评材料 | H23: =VLOOKUP(A:A,'全量进度管理'!A:L,9,FALSE) -> 基本满足 | I23: =VLOOKUP(A:A,'全量进度管理'!A:L,10,FALSE) -> 讲评页面书写流畅度有待优化 | K23: =VLOOKUP(A:A,'全量进度管理'!A:L,12,FALSE) -> 待排期
A24: 27 | D24: =VLOOKUP(A:A,'全量进度管理'!A:L,4,FALSE) -> 学生查看数据 | E24: =VLOOKUP(A:A,'全量进度管理'!A:L,5,FALSE) -> 学生查看单次作业数据 | F24: =VLOOKUP(A:A,'全量进度管理'!A:L,6,FALSE) -> 高 | G24: =VLOOKUP(A:A,'全量进度管理'!A:L,8,FALSE) -> 支持学生查看单次测验数据 | H24: =VLOOKUP(A:A,'全量进度管理'!A:L,9,FALSE) -> 完全满足
A25: 28 | E25: =VLOOKUP(A:A,'全量进度管理'!A:L,5,FALSE) -> 学生查看阶段学情 | F25: =VLOOKUP(A:A,'全量进度管理'!A:L,6,FALSE) -> 高 | G25: =VLOOKUP(A:A,'全量进度管理'!A:L,8,FALSE) -> 支持学生查看阶段学情 | H25: =VLOOKUP(A:A,'全量进度管理'!A:L,9,FALSE) -> 完全满足
A26: 29 | D26: =VLOOKUP(A:A,'全量进度管理'!A:L,4,FALSE) -> 学生基于学情的自习 | E26: =VLOOKUP(A:A,'全量进度管理'!A:L,5,FALSE) -> 学生自习室：基于学情查看知识讲解、进行巩固练习 | F26: =VLOOKUP(A:A,'全量进度管理'!A:L,6,FALSE) -> 低 | G26: =VLOOKUP(A:A,'全量进度管理'!A:L,8,FALSE) -> 无 | H26: =VLOOKUP(A:A,'全量进度管理'!A:L,9,FALSE) -> 完全不满足 | I26: =VLOOKUP(A:A,'全量进度管理'!A:L,10,FALSE) -> 支持学生基于学情进行知识、错题巩固 | J26: =VLOOKUP(A:A,'全量进度管理'!A:L,11,FALSE) -> 46265 | K26: =VLOOKUP(A:A,'全量进度管理'!A:L,12,FALSE) -> 已排期
A27: 30 | C27: =VLOOKUP(A:A,'全量进度管理'!A:L,3,FALSE) -> 错题的管理与运用 | D27: =VLOOKUP(A:A,'全量进度管理'!A:L,4,FALSE) -> 教师查看并应用错题 | E27: =VLOOKUP(A:A,'全量进度管理'!A:L,5,FALSE) -> 教师查看班级错题 | F27: =VLOOKUP(A:A,'全量进度管理'!A:L,6,FALSE) -> 高 | G27: =VLOOKUP(A:A,'全量进度管理'!A:L,8,FALSE) -> 支持教师查看班级错题 | H27: =VLOOKUP(A:A,'全量进度管理'!A:L,9,FALSE) -> 完全满足
A28: 31 | E28: =VLOOKUP(A:A,'全量进度管理'!A:L,5,FALSE) -> 基于班级错题的应用 | F28: =VLOOKUP(A:A,'全量进度管理'!A:L,6,FALSE) -> 中 | G28: =VLOOKUP(A:A,'全量进度管理'!A:L,8,FALSE) -> 支持教师基于错题进行组卷练习 | H28: =VLOOKUP(A:A,'全量进度管理'!A:L,9,FALSE) -> 完全满足
A29: 33 | D29: =VLOOKUP(A:A,'全量进度管理'!A:L,4,FALSE) -> 学生查看并管理错题 | E29: =VLOOKUP(A:A,'全量进度管理'!A:L,5,FALSE) -> 学生查看并管理个人错题 | F29: =VLOOKUP(A:A,'全量进度管理'!A:L,6,FALSE) -> 高 | G29: =VLOOKUP(A:A,'全量进度管理'!A:L,8,FALSE) -> 支持学生查看并管理个人错题 | H29: =VLOOKUP(A:A,'全量进度管理'!A:L,9,FALSE) -> 完全满足
A30: 34 | B30: =VLOOKUP(A:A,'全量进度管理'!A:L,2,FALSE) -> 教辅作业数据采集 | C30: =VLOOKUP(A:A,'全量进度管理'!A:L,3,FALSE) -> 扫描 | D30: =VLOOKUP(A:A,'全量进度管理'!A:L,4,FALSE) -> 支持扫描教辅活页 | E30: =VLOOKUP(A:A,'全量进度管理'!A:L,5,FALSE) -> 固定教辅全学科支持 | F30: =VLOOKUP(A:A,'全量进度管理'!A:L,6,FALSE) -> 高 | G30: =VLOOKUP(A:A,'全量进度管理'!A:L,8,FALSE) -> 暂不支持英语学科，其他学科支持 | H30: =VLOOKUP(A:A,'全量进度管理'!A:L,9,FALSE) -> 基本满足 | I30: =VLOOKUP(A:A,'全量进度管理'!A:L,10,FALSE) -> 拓展英语学科的教辅扫描和识别 | K30: =VLOOKUP(A:A,'全量进度管理'!A:L,12,FALSE) -> 待排期
A31: 35 | C31: =VLOOKUP(A:A,'全量进度管理'!A:L,3,FALSE) -> 异常处理 | D31: =VLOOKUP(A:A,'全量进度管理'!A:L,4,FALSE) -> 支持手动处理各类异常 | E31: =VLOOKUP(A:A,'全量进度管理'!A:L,5,FALSE) -> 教师能手动处理各类异常 | F31: =VLOOKUP(A:A,'全量进度管理'!A:L,6,FALSE) -> 高 | G31: =VLOOKUP(A:A,'全量进度管理'!A:L,8,FALSE) -> 支持教师、运营处理每次扫描数据的异常内容 | H31: =VLOOKUP(A:A,'全量进度管理'!A:L,9,FALSE) -> 完全满足
A32: 36 | C32: =VLOOKUP(A:A,'全量进度管理'!A:L,3,FALSE) -> 识别与批改 | D32: =VLOOKUP(A:A,'全量进度管理'!A:L,4,FALSE) -> 识别结果校验 | E32: =VLOOKUP(A:A,'全量进度管理'!A:L,5,FALSE) -> 支持快速检验采集结果的准确性 | F32: =VLOOKUP(A:A,'全量进度管理'!A:L,6,FALSE) -> 中 | G32: =VLOOKUP(A:A,'全量进度管理'!A:L,8,FALSE) -> 无 | H32: =VLOOKUP(A:A,'全量进度管理'!A:L,9,FALSE) -> 完全不满足 | I32: =VLOOKUP(A:A,'全量进度管理'!A:L,10,FALSE) -> 支持集中呈现可能识别有误的数据，支持教师手动修正 | J32: =VLOOKUP(A:A,'全量进度管理'!A:L,11,FALSE) -> 46203 | K32: =VLOOKUP(A:A,'全量进度管理'!A:L,12,FALSE) -> 开发中
A33: 37 | D33: =VLOOKUP(A:A,'全量进度管理'!A:L,4,FALSE) -> 识别准确率高 | E33: =VLOOKUP(A:A,'全量进度管理'!A:L,5,FALSE) -> 识别准确率高 | F33: =VLOOKUP(A:A,'全量进度管理'!A:L,6,FALSE) -> 中 | G33: =VLOOKUP(A:A,'全量进度管理'!A:L,8,FALSE) -> 由于教辅批阅随意，很多规律不好总结给AI，导致部分内容识别可能存在偏差 | H33: =VLOOKUP(A:A,'全量进度管理'!A:L,9,FALSE) -> 基本满足 | I33: =VLOOKUP(A:A,'全量进度管理'!A:L,10,FALSE) -> 1. 持续优化识别 2. 规范教师批阅行为
A34: 38 | D34: =VLOOKUP(A:A,'全量进度管理'!A:L,4,FALSE) -> AI自动批阅 | E34: =VLOOKUP(A:A,'全量进度管理'!A:L,5,FALSE) -> 填空题 | F34: =VLOOKUP(A:A,'全量进度管理'!A:L,6,FALSE) -> 中 | G34: =VLOOKUP(A:A,'全量进度管理'!A:L,8,FALSE) -> 无 | H34: =VLOOKUP(A:A,'全量进度管理'!A:L,9,FALSE) -> 完全不满足 | I34: =VLOOKUP(A:A,'全量进度管理'!A:L,10,FALSE) -> 优先实现英语填空题的自动批阅 | J34: =VLOOKUP(A:A,'全量进度管理'!A:L,11,FALSE) -> 46265 | K34: =VLOOKUP(A:A,'全量进度管理'!A:L,12,FALSE) -> 已排期
A35: 39 | E35: =VLOOKUP(A:A,'全量进度管理'!A:L,5,FALSE) -> 主观题 | F35: =VLOOKUP(A:A,'全量进度管理'!A:L,6,FALSE) -> 低 | G35: =VLOOKUP(A:A,'全量进度管理'!A:L,8,FALSE) -> 无 | H35: =VLOOKUP(A:A,'全量进度管理'!A:L,9,FALSE) -> 完全不满足
A36: 40 | E36: =VLOOKUP(A:A,'全量进度管理'!A:L,5,FALSE) -> 留痕批阅 | F36: =VLOOKUP(A:A,'全量进度管理'!A:L,6,FALSE) -> 非必须 | G36: =VLOOKUP(A:A,'全量进度管理'!A:L,8,FALSE) -> 无 | H36: =VLOOKUP(A:A,'全量进度管理'!A:L,9,FALSE) -> 完全不满足
A37: 41 | C37: =VLOOKUP(A:A,'全量进度管理'!A:L,3,FALSE) -> 数据查看与应用 | D37: =VLOOKUP(A:A,'全量进度管理'!A:L,4,FALSE) -> 教师查看教辅数据 | E37: =VLOOKUP(A:A,'全量进度管理'!A:L,5,FALSE) -> 按书查看节点数据 | F37: =VLOOKUP(A:A,'全量进度管理'!A:L,6,FALSE) -> 高 | G37: =VLOOKUP(A:A,'全量进度管理'!A:L,8,FALSE) -> 支持按节点查看数据 | H37: =VLOOKUP(A:A,'全量进度管理'!A:L,9,FALSE) -> 完全满足
A38: 42 | E38: =VLOOKUP(A:A,'全量进度管理'!A:L,5,FALSE) -> 教辅数据纳入阶段学情 | F38: =VLOOKUP(A:A,'全量进度管理'!A:L,6,FALSE) -> 高 | G38: =VLOOKUP(A:A,'全量进度管理'!A:L,8,FALSE) -> 无 | H38: =VLOOKUP(A:A,'全量进度管理'!A:L,9,FALSE) -> 完全不满足 | I38: =VLOOKUP(A:A,'全量进度管理'!A:L,10,FALSE) -> 支持查看教辅阶段数据 | J38: =VLOOKUP(A:A,'全量进度管理'!A:L,11,FALSE) -> 46265 | K38: =VLOOKUP(A:A,'全量进度管理'!A:L,12,FALSE) -> 已排期
A39: 43 | D39: =VLOOKUP(A:A,'全量进度管理'!A:L,4,FALSE) -> 基于教辅数据讲评 | E39: =VLOOKUP(A:A,'全量进度管理'!A:L,5,FALSE) -> 支持教师对教辅数据进行讲评 | F39: =VLOOKUP(A:A,'全量进度管理'!A:L,6,FALSE) -> 中 | G39: =VLOOKUP(A:A,'全量进度管理'!A:L,8,FALSE) -> 无 | H39: =VLOOKUP(A:A,'全量进度管理'!A:L,9,FALSE) -> 完全不满足 | I39: =VLOOKUP(A:A,'全量进度管理'!A:L,10,FALSE) -> 支持教师基于教辅数据进行讲评 | J39: =VLOOKUP(A:A,'全量进度管理'!A:L,11,FALSE) -> 46234 | K39: =VLOOKUP(A:A,'全量进度管理'!A:L,12,FALSE) -> 开发中
A40: 44 | D40: =VLOOKUP(A:A,'全量进度管理'!A:L,4,FALSE) -> 学生查看教辅数据 | E40: =VLOOKUP(A:A,'全量进度管理'!A:L,5,FALSE) -> 按书查看节点数据 | F40: =VLOOKUP(A:A,'全量进度管理'!A:L,6,FALSE) -> 高 | G40: =VLOOKUP(A:A,'全量进度管理'!A:L,8,FALSE) -> 支持按节点查看数据 | H40: =VLOOKUP(A:A,'全量进度管理'!A:L,9,FALSE) -> 完全满足
...

Sheet 初中录播教辅问题解决
B1: 所属场景 | C1: 环节 | D1: 商用目标功能 | E1: 商用细分需求 | F1: 商用必备等级 | G1: 闻道作业现状 | H1: 是否满足商用目标 | I1: 后续计划 | J1: 计划完成时间 | K1: 状态
A2: 1 | B2: =VLOOKUP(A:A,'全量进度管理'!A:L,2,FALSE) -> 校本资源建设与管理 | C2: =VLOOKUP(A:A,'全量进度管理'!A:L,3,FALSE) -> 校本资源建设 | D2: =VLOOKUP(A:A,'全量进度管理'!A:L,4,FALSE) -> 校本资源建设与管理闭环 | E2: =VLOOKUP(A:A,'全量进度管理'!A:L,5,FALSE) -> 题单资源的便捷自主建设 | F2: =VLOOKUP(A:A,'全量进度管理'!A:L,6,FALSE) -> 高 | G2: =VLOOKUP(A:A,'全量进度管理'!A:L,8,FALSE) -> 支持教师自主建设题单；但欠缺一定的便捷性 | H2: =VLOOKUP(A:A,'全量进度管理'!A:L,9,FALSE) -> 基本满足 | I2: =VLOOKUP(A:A,'全量进度管理'!A:L,10,FALSE) -> 持续优化便捷性和AI识别准确性 | J2: =VLOOKUP(A:A,'全量进度管理'!A:L,11,FALSE) -> 46234 | K2: =VLOOKUP(A:A,'全量进度管理'!A:L,12,FALSE) -> 开发中
A3: 2 | E3: =VLOOKUP(A:A,'全量进度管理'!A:L,5,FALSE) -> 课件资源的便捷建设 | F3: =VLOOKUP(A:A,'全量进度管理'!A:L,6,FALSE) -> 非必须 | G3: =VLOOKUP(A:A,'全量进度管理'!A:L,8,FALSE) -> 无 | H3: =VLOOKUP(A:A,'全量进度管理'!A:L,9,FALSE) -> 完全不满足 | K3: =VLOOKUP(A:A,'全量进度管理'!A:L,12,FALSE) -> 暂不响应
A4: 3 | E4: =VLOOKUP(A:A,'全量进度管理'!A:L,5,FALSE) -> 校本资源数据看板 | F4: =VLOOKUP(A:A,'全量进度管理'!A:L,6,FALSE) -> 低 | G4: =VLOOKUP(A:A,'全量进度管理'!A:L,8,FALSE) -> 无 | H4: =VLOOKUP(A:A,'全量进度管理'!A:L,9,FALSE) -> 完全不满足 | K4: =VLOOKUP(A:A,'全量进度管理'!A:L,12,FALSE) -> 待排期
A5: 4 | E5: =VLOOKUP(A:A,'全量进度管理'!A:L,5,FALSE) -> 校本教辅的建设与使用（代为建设） | F5: =VLOOKUP(A:A,'全量进度管理'!A:L,6,FALSE) -> 高 | G5: =VLOOKUP(A:A,'全量进度管理'!A:L,8,FALSE) -> 无 | H5: =VLOOKUP(A:A,'全量进度管理'!A:L,9,FALSE) -> 完全不满足 | I5: =VLOOKUP(A:A,'全量进度管理'!A:L,10,FALSE) -> 支持为学校建设校本教辅，且可使用 | K5: =VLOOKUP(A:A,'全量进度管理'!A:L,12,FALSE) -> 待排期
A6: 5 | B6: =VLOOKUP(A:A,'全量进度管理'!A:L,2,FALSE) -> 日常作业与练习 | C6: =VLOOKUP(A:A,'全量进度管理'!A:L,3,FALSE) -> 组卷 | D6: =VLOOKUP(A:A,'全量进度管理'!A:L,4,FALSE) -> 多来源兼容 | E6: =VLOOKUP(A:A,'全量进度管理'!A:L,5,FALSE) -> 平台内题单资源使用 | F6: =VLOOKUP(A:A,'全量进度管理'!A:L,6,FALSE) -> 高 | G6: =VLOOKUP(A:A,'全量进度管理'!A:L,8,FALSE) -> 支持用户直接使用平台内题单 | H6: =VLOOKUP(A:A,'全量进度管理'!A:L,9,FALSE) -> 完全满足
A7: 6 | E7: =VLOOKUP(A:A,'全量进度管理'!A:L,5,FALSE) -> 丰富的题库，支持题库选题组卷 | F7: =VLOOKUP(A:A,'全量进度管理'!A:L,6,FALSE) -> 高 | G7: =VLOOKUP(A:A,'全量进度管理'!A:L,8,FALSE) -> 接入学科网，支持用户从我司题库或学科网选题进行组卷 | H7: =VLOOKUP(A:A,'全量进度管理'!A:L,9,FALSE) -> 完全满足 | I7: =VLOOKUP(A:A,'全量进度管理'!A:L,10,FALSE) -> 学科网刚接入，可能在后续还有一些适配相关优化，但需使用一段时间后才能发现问题 | K7: =VLOOKUP(A:A,'全量进度管理'!A:L,12,FALSE) -> 待排期
A8: 7 | E8: =VLOOKUP(A:A,'全量进度管理'!A:L,5,FALSE) -> 自有试卷的快速使用 | F8: =VLOOKUP(A:A,'全量进度管理'!A:L,6,FALSE) -> 高 | G8: =VLOOKUP(A:A,'全量进度管理'!A:L,8,FALSE) -> 支持AI切题识别后组卷，但还无法满足“快速”的要求 | H8: =VLOOKUP(A:A,'全量进度管理'!A:L,9,FALSE) -> 基本满足 | I8: =VLOOKUP(A:A,'全量进度管理'!A:L,10,FALSE) -> 支持现成题单快速添加标记后使用，后续再完善试题内容 | K8: =VLOOKUP(A:A,'全量进度管理'!A:L,12,FALSE) -> 待排期
A9: 8 | E9: =VLOOKUP(A:A,'全量进度管理'!A:L,5,FALSE) -> 基于学情的智能组卷 | F9: =VLOOKUP(A:A,'全量进度管理'!A:L,6,FALSE) -> 低 | G9: =VLOOKUP(A:A,'全量进度管理'!A:L,8,FALSE) -> 无 | H9: =VLOOKUP(A:A,'全量进度管理'!A:L,9,FALSE) -> 完全不满足 | I9: =VLOOKUP(A:A,'全量进度管理'!A:L,10,FALSE) -> 支持教师基于学情进行智能组卷 | K9: =VLOOKUP(A:A,'全量进度管理'!A:L,12,FALSE) -> 待排期
A10: 9 | C10: =VLOOKUP(A:A,'全量进度管理'!A:L,3,FALSE) -> 生成答题卡 | D10: =VLOOKUP(A:A,'全量进度管理'!A:L,4,FALSE) -> 支持常见纸张 | E10: =VLOOKUP(A:A,'全量进度管理'!A:L,5,FALSE) -> 支持学校常用纸张 | F10: =VLOOKUP(A:A,'全量进度管理'!A:L,6,FALSE) -> 高 | G10: =VLOOKUP(A:A,'全量进度管理'!A:L,8,FALSE) -> 支持A3、A4、B4、8K常用纸张大小 | H10: =VLOOKUP(A:A,'全量进度管理'!A:L,9,FALSE) -> 完全满足
A11: 10 | E11: =VLOOKUP(A:A,'全量进度管理'!A:L,5,FALSE) -> 支持先制卡后制题 | F11: =VLOOKUP(A:A,'全量进度管理'!A:L,6,FALSE) -> 低 | G11: =VLOOKUP(A:A,'全量进度管理'!A:L,8,FALSE) -> 无 | H11: =VLOOKUP(A:A,'全量进度管理'!A:L,9,FALSE) -> 完全不满足 | I11: =VLOOKUP(A:A,'全量进度管理'!A:L,10,FALSE) -> 考试场景拓展后兼容 | K11: =VLOOKUP(A:A,'全量进度管理'!A:L,12,FALSE) -> 待排期
A12: 11 | C12: =VLOOKUP(A:A,'全量进度管理'!A:L,3,FALSE) -> 扫描 | D12: =VLOOKUP(A:A,'全量进度管理'!A:L,4,FALSE) -> 多设备兼容 | E12: =VLOOKUP(A:A,'全量进度管理'!A:L,5,FALSE) -> 支持主流品牌扫描仪的直连 | F12: =VLOOKUP(A:A,'全量进度管理'!A:L,6,FALSE) -> 中 | G12: =VLOOKUP(A:A,'全量进度管理'!A:L,8,FALSE) -> 理论上基本支持，但部分机器可能存在兼容问题，需具体型号具体观察和解决 | H12: =VLOOKUP(A:A,'全量进度管理'!A:L,9,FALSE) -> 基本满足 | I12: =VLOOKUP(A:A,'全量进度管理'!A:L,10,FALSE) -> 新增新设备使用时，提前调试，及时发现问题解决问题
A13: 12 | D13: =VLOOKUP(A:A,'全量进度管理'!A:L,4,FALSE) -> 一键式便捷扫描 | E13: =VLOOKUP(A:A,'全量进度管理'!A:L,5,FALSE) -> 扫描开始后自动进行，无额外人工动作 | F13: =VLOOKUP(A:A,'全量进度管理'!A:L,6,FALSE) -> 中 | G13: =VLOOKUP(A:A,'全量进度管理'!A:L,8,FALSE) -> 支持一键快速扫描 | H13: =VLOOKUP(A:A,'全量进度管理'!A:L,9,FALSE) -> 完全满足
A14: 13 | C14: =VLOOKUP(A:A,'全量进度管理'!A:L,3,FALSE) -> 异常处理 | D14: =VLOOKUP(A:A,'全量进度管理'!A:L,4,FALSE) -> 异常数据尽量少 | E14: =VLOOKUP(A:A,'全量进度管理'!A:L,5,FALSE) -> 有规律的异常可以系统自动处理 | F14: =VLOOKUP(A:A,'全量进度管理'!A:L,6,FALSE) -> 非必须 | G14: =VLOOKUP(A:A,'全量进度管理'!A:L,8,FALSE) -> 部分能总结出规律的异常已加入系统规则，自动处理；但仍需持续观察异常数据， | H14: =VLOOKUP(A:A,'全量进度管理'!A:L,9,FALSE) -> 完全满足
A15: 14 | D15: =VLOOKUP(A:A,'全量进度管理'!A:L,4,FALSE) -> 支持手动处理各类异常 | E15: =VLOOKUP(A:A,'全量进度管理'!A:L,5,FALSE) -> 教师能手动处理各类异常 | F15: =VLOOKUP(A:A,'全量进度管理'!A:L,6,FALSE) -> 高 | G15: =VLOOKUP(A:A,'全量进度管理'!A:L,8,FALSE) -> 支持教师、运营处理每次扫描数据的异常内容 | H15: =VLOOKUP(A:A,'全量进度管理'!A:L,9,FALSE) -> 完全满足
A16: 15 | E16: =VLOOKUP(A:A,'全量进度管理'!A:L,5,FALSE) -> 操作便捷 | F16: =VLOOKUP(A:A,'全量进度管理'!A:L,6,FALSE) -> 中 | G16: =VLOOKUP(A:A,'全量进度管理'!A:L,8,FALSE) -> 交互复杂，存在一定的优化空间 | H16: =VLOOKUP(A:A,'全量进度管理'!A:L,9,FALSE) -> 基本满足 | K16: =VLOOKUP(A:A,'全量进度管理'!A:L,12,FALSE) -> 待排期
A17: 16 | C17: =VLOOKUP(A:A,'全量进度管理'!A:L,3,FALSE) -> 识别与批改 | D17: =VLOOKUP(A:A,'全量进度管理'!A:L,4,FALSE) -> 识别准确率高 | E17: =VLOOKUP(A:A,'全量进度管理'!A:L,5,FALSE) -> AI自动识别客观题和分数准确率>99.5% | F17: =VLOOKUP(A:A,'全量进度管理'!A:L,6,FALSE) -> 高 | G17: =VLOOKUP(A:A,'全量进度管理'!A:L,8,FALSE) -> 准确率稳定在99.5%~99.8%，处于行业中上水平 | H17: =VLOOKUP(A:A,'全量进度管理'!A:L,9,FALSE) -> 完全满足
A18: 17 | D18: =VLOOKUP(A:A,'全量进度管理'!A:L,4,FALSE) -> 识别结果校验 | E18: =VLOOKUP(A:A,'全量进度管理'!A:L,5,FALSE) -> 支持快速检验采集结果的准确性 | F18: =VLOOKUP(A:A,'全量进度管理'!A:L,6,FALSE) -> 中 | G18: =VLOOKUP(A:A,'全量进度管理'!A:L,8,FALSE) -> 支持集中呈现可能识别有误的数据，支持教师手动修正 | H18: =VLOOKUP(A:A,'全量进度管理'!A:L,9,FALSE) -> 完全满足
A19: 18 | D19: =VLOOKUP(A:A,'全量进度管理'!A:L,4,FALSE) -> AI自动批阅 | E19: =VLOOKUP(A:A,'全量进度管理'!A:L,5,FALSE) -> 作文类 | F19: =VLOOKUP(A:A,'全量进度管理'!A:L,6,FALSE) -> 低 | G19: =VLOOKUP(A:A,'全量进度管理'!A:L,8,FALSE) -> 支持英语作文批阅，但是语文作文还欠缺 | H19: =VLOOKUP(A:A,'全量进度管理'!A:L,9,FALSE) -> 基本满足 | I19: =VLOOKUP(A:A,'全量进度管理'!A:L,10,FALSE) -> 支持语文作文 | K19: =VLOOKUP(A:A,'全量进度管理'!A:L,12,FALSE) -> 待排期
A20: 19 | E20: =VLOOKUP(A:A,'全量进度管理'!A:L,5,FALSE) -> 填空题 | F20: =VLOOKUP(A:A,'全量进度管理'!A:L,6,FALSE) -> 中 | G20: =VLOOKUP(A:A,'全量进度管理'!A:L,8,FALSE) -> 无 | H20: =VLOOKUP(A:A,'全量进度管理'!A:L,9,FALSE) -> 完全不满足 | I20: =VLOOKUP(A:A,'全量进度管理'!A:L,10,FALSE) -> 优先实现英语填空题的自动批阅 | J20: =VLOOKUP(A:A,'全量进度管理'!A:L,11,FALSE) -> 46265 | K20: =VLOOKUP(A:A,'全量进度管理'!A:L,12,FALSE) -> 已排期
A21: 20 | E21: =VLOOKUP(A:A,'全量进度管理'!A:L,5,FALSE) -> 主观题 | F21: =VLOOKUP(A:A,'全量进度管理'!A:L,6,FALSE) -> 中 | G21: =VLOOKUP(A:A,'全量进度管理'!A:L,8,FALSE) -> 无 | H21: =VLOOKUP(A:A,'全量进度管理'!A:L,9,FALSE) -> 完全不满足
A22: 21 | E22: =VLOOKUP(A:A,'全量进度管理'!A:L,5,FALSE) -> 留痕批阅 | F22: =VLOOKUP(A:A,'全量进度管理'!A:L,6,FALSE) -> 中 | G22: =VLOOKUP(A:A,'全量进度管理'!A:L,8,FALSE) -> 无 | H22: =VLOOKUP(A:A,'全量进度管理'!A:L,9,FALSE) -> 完全不满足
A23: 22 | D23: =VLOOKUP(A:A,'全量进度管理'!A:L,4,FALSE) -> 在线批阅 | E23: =VLOOKUP(A:A,'全量进度管理'!A:L,5,FALSE) -> 支持教师在线批阅 | F23: =VLOOKUP(A:A,'全量进度管理'!A:L,6,FALSE) -> 低 | G23: =VLOOKUP(A:A,'全量进度管理'!A:L,8,FALSE) -> 支持教师在线批阅题单 | H23: =VLOOKUP(A:A,'全量进度管理'!A:L,9,FALSE) -> 完全满足
A24: 23 | C24: =VLOOKUP(A:A,'全量进度管理'!A:L,3,FALSE) -> 数据查看与应用 | D24: =VLOOKUP(A:A,'全量进度管理'!A:L,4,FALSE) -> 教师查看数据 | E24: =VLOOKUP(A:A,'全量进度管理'!A:L,5,FALSE) -> 教师查看单次测验数据 | F24: =VLOOKUP(A:A,'全量进度管理'!A:L,6,FALSE) -> 高 | G24: =VLOOKUP(A:A,'全量进度管理'!A:L,8,FALSE) -> 支持教师查看单次测验数据 | H24: =VLOOKUP(A:A,'全量进度管理'!A:L,9,FALSE) -> 完全满足
A25: 24 | E25: =VLOOKUP(A:A,'全量进度管理'!A:L,5,FALSE) -> 教师查看阶段数据 | F25: =VLOOKUP(A:A,'全量进度管理'!A:L,6,FALSE) -> 高 | G25: =VLOOKUP(A:A,'全量进度管理'!A:L,8,FALSE) -> 支持教师查看阶段数据，但是老版本；与当前业务的融合性不够 | H25: =VLOOKUP(A:A,'全量进度管理'!A:L,9,FALSE) -> 基本满足 | I25: =VLOOKUP(A:A,'全量进度管理'!A:L,10,FALSE) -> 升级阶段学情 | K25: =VLOOKUP(A:A,'全量进度管理'!A:L,12,FALSE) -> 待排期
A26: 25 | E26: =VLOOKUP(A:A,'全量进度管理'!A:L,5,FALSE) -> 不同角色校管查看数据 | F26: =VLOOKUP(A:A,'全量进度管理'!A:L,6,FALSE) -> 高 | G26: =VLOOKUP(A:A,'全量进度管理'!A:L,8,FALSE) -> 支持不同角色查看年级数据 | H26: =VLOOKUP(A:A,'全量进度管理'!A:L,9,FALSE) -> 完全满足 | I26: =VLOOKUP(A:A,'全量进度管理'!A:L,10,FALSE) -> 由于三方系统原因，导致权限会有部分放大，但总体不影响使用；后续优化权限 | K26: =VLOOKUP(A:A,'全量进度管理'!A:L,12,FALSE) -> 待排期
A27: 26 | D27: =VLOOKUP(A:A,'全量进度管理'!A:L,4,FALSE) -> 教师讲评 | E27: =VLOOKUP(A:A,'全量进度管理'!A:L,5,FALSE) -> 支持教师基于题单进行讲评 | F27: =VLOOKUP(A:A,'全量进度管理'!A:L,6,FALSE) -> 中 | G27: =VLOOKUP(A:A,'全量进度管理'!A:L,8,FALSE) -> 支持讲评、导出讲评材料 | H27: =VLOOKUP(A:A,'全量进度管理'!A:L,9,FALSE) -> 基本满足 | I27: =VLOOKUP(A:A,'全量进度管理'!A:L,10,FALSE) -> 讲评页面书写流畅度有待优化 | K27: =VLOOKUP(A:A,'全量进度管理'!A:L,12,FALSE) -> 待排期
A28: 27 | D28: =VLOOKUP(A:A,'全量进度管理'!A:L,4,FALSE) -> 学生查看数据 | E28: =VLOOKUP(A:A,'全量进度管理'!A:L,5,FALSE) -> 学生查看单次作业数据 | F28: =VLOOKUP(A:A,'全量进度管理'!A:L,6,FALSE) -> 高 | G28: =VLOOKUP(A:A,'全量进度管理'!A:L,8,FALSE) -> 支持学生查看单次测验数据 | H28: =VLOOKUP(A:A,'全量进度管理'!A:L,9,FALSE) -> 完全满足
A29: 28 | E29: =VLOOKUP(A:A,'全量进度管理'!A:L,5,FALSE) -> 学生查看阶段学情 | F29: =VLOOKUP(A:A,'全量进度管理'!A:L,6,FALSE) -> 高 | G29: =VLOOKUP(A:A,'全量进度管理'!A:L,8,FALSE) -> 支持学生查看阶段学情 | H29: =VLOOKUP(A:A,'全量进度管理'!A:L,9,FALSE) -> 完全满足
A30: 29 | D30: =VLOOKUP(A:A,'全量进度管理'!A:L,4,FALSE) -> 学生基于学情的自习 | E30: =VLOOKUP(A:A,'全量进度管理'!A:L,5,FALSE) -> 学生自习室：基于学情查看知识讲解、进行巩固练习 | F30: =VLOOKUP(A:A,'全量进度管理'!A:L,6,FALSE) -> 低 | G30: =VLOOKUP(A:A,'全量进度管理'!A:L,8,FALSE) -> 无 | H30: =VLOOKUP(A:A,'全量进度管理'!A:L,9,FALSE) -> 完全不满足 | I30: =VLOOKUP(A:A,'全量进度管理'!A:L,10,FALSE) -> 支持学生基于学情进行知识、错题巩固 | J30: =VLOOKUP(A:A,'全量进度管理'!A:L,11,FALSE) -> 46265 | K30: =VLOOKUP(A:A,'全量进度管理'!A:L,12,FALSE) -> 已排期
A31: 30 | C31: =VLOOKUP(A:A,'全量进度管理'!A:L,3,FALSE) -> 错题的管理与运用 | D31: =VLOOKUP(A:A,'全量进度管理'!A:L,4,FALSE) -> 教师查看并应用错题 | E31: =VLOOKUP(A:A,'全量进度管理'!A:L,5,FALSE) -> 教师查看班级错题 | F31: =VLOOKUP(A:A,'全量进度管理'!A:L,6,FALSE) -> 高 | G31: =VLOOKUP(A:A,'全量进度管理'!A:L,8,FALSE) -> 支持教师查看班级错题 | H31: =VLOOKUP(A:A,'全量进度管理'!A:L,9,FALSE) -> 完全满足
A32: 31 | E32: =VLOOKUP(A:A,'全量进度管理'!A:L,5,FALSE) -> 基于班级错题的应用 | F32: =VLOOKUP(A:A,'全量进度管理'!A:L,6,FALSE) -> 中 | G32: =VLOOKUP(A:A,'全量进度管理'!A:L,8,FALSE) -> 支持教师基于错题进行组卷练习 | H32: =VLOOKUP(A:A,'全量进度管理'!A:L,9,FALSE) -> 完全满足
A33: 32 | E33: =VLOOKUP(A:A,'全量进度管理'!A:L,5,FALSE) -> 教师查看年级错题 | F33: =VLOOKUP(A:A,'全量进度管理'!A:L,6,FALSE) -> 低 | G33: =VLOOKUP(A:A,'全量进度管理'!A:L,8,FALSE) -> 无 | H33: =VLOOKUP(A:A,'全量进度管理'!A:L,9,FALSE) -> 完全不满足 | I33: =VLOOKUP(A:A,'全量进度管理'!A:L,10,FALSE) -> 支持教师查看并应用年级错题 | K33: =VLOOKUP(A:A,'全量进度管理'!A:L,12,FALSE) -> 待排期
A34: 65 | E34: =VLOOKUP(A:A,'全量进度管理'!A:L,5,FALSE) -> 基于错题自动生成学生个性化作业且可回采数据 | F34: =VLOOKUP(A:A,'全量进度管理'!A:L,6,FALSE) -> 中 | G34: =VLOOKUP(A:A,'全量进度管理'!A:L,8,FALSE) -> 可以生成统一作业，个性化作业暂不支持 | H34: =VLOOKUP(A:A,'全量进度管理'!A:L,9,FALSE) -> 基本满足
A35: 33 | D35: =VLOOKUP(A:A,'全量进度管理'!A:L,4,FALSE) -> 学生查看并管理错题 | E35: =VLOOKUP(A:A,'全量进度管理'!A:L,5,FALSE) -> 学生查看并管理个人错题 | F35: =VLOOKUP(A:A,'全量进度管理'!A:L,6,FALSE) -> 高 | G35: =VLOOKUP(A:A,'全量进度管理'!A:L,8,FALSE) -> 支持学生查看并管理个人错题 | H35: =VLOOKUP(A:A,'全量进度管理'!A:L,9,FALSE) -> 完全满足
A36: 34 | B36: =VLOOKUP(A:A,'全量进度管理'!A:L,2,FALSE) -> 教辅作业数据采集 | C36: =VLOOKUP(A:A,'全量进度管理'!A:L,3,FALSE) -> 扫描 | D36: =VLOOKUP(A:A,'全量进度管理'!A:L,4,FALSE) -> 支持扫描教辅活页 | E36: =VLOOKUP(A:A,'全量进度管理'!A:L,5,FALSE) -> 固定教辅全学科支持 | F36: =VLOOKUP(A:A,'全量进度管理'!A:L,6,FALSE) -> 高 | G36: =VLOOKUP(A:A,'全量进度管理'!A:L,8,FALSE) -> 暂不支持英语学科，其他学科支持 | H36: =VLOOKUP(A:A,'全量进度管理'!A:L,9,FALSE) -> 基本满足 | I36: =VLOOKUP(A:A,'全量进度管理'!A:L,10,FALSE) -> 拓展英语学科的教辅扫描和识别 | K36: =VLOOKUP(A:A,'全量进度管理'!A:L,12,FALSE) -> 待排期
A37: 35 | C37: =VLOOKUP(A:A,'全量进度管理'!A:L,3,FALSE) -> 异常处理 | D37: =VLOOKUP(A:A,'全量进度管理'!A:L,4,FALSE) -> 支持手动处理各类异常 | E37: =VLOOKUP(A:A,'全量进度管理'!A:L,5,FALSE) -> 教师能手动处理各类异常 | F37: =VLOOKUP(A:A,'全量进度管理'!A:L,6,FALSE) -> 高 | G37: =VLOOKUP(A:A,'全量进度管理'!A:L,8,FALSE) -> 支持教师、运营处理每次扫描数据的异常内容 | H37: =VLOOKUP(A:A,'全量进度管理'!A:L,9,FALSE) -> 完全满足
A38: 36 | C38: =VLOOKUP(A:A,'全量进度管理'!A:L,3,FALSE) -> 识别与批改 | D38: =VLOOKUP(A:A,'全量进度管理'!A:L,4,FALSE) -> 识别结果校验 | E38: =VLOOKUP(A:A,'全量进度管理'!A:L,5,FALSE) -> 支持快速检验采集结果的准确性 | F38: =VLOOKUP(A:A,'全量进度管理'!A:L,6,FALSE) -> 中 | G38: =VLOOKUP(A:A,'全量进度管理'!A:L,8,FALSE) -> 无 | H38: =VLOOKUP(A:A,'全量进度管理'!A:L,9,FALSE) -> 完全不满足 | I38: =VLOOKUP(A:A,'全量进度管理'!A:L,10,FALSE) -> 支持集中呈现可能识别有误的数据，支持教师手动修正 | J38: =VLOOKUP(A:A,'全量进度管理'!A:L,11,FALSE) -> 46203 | K38: =VLOOKUP(A:A,'全量进度管理'!A:L,12,FALSE) -> 开发中
A39: 37 | D39: =VLOOKUP(A:A,'全量进度管理'!A:L,4,FALSE) -> 识别准确率高 | E39: =VLOOKUP(A:A,'全量进度管理'!A:L,5,FALSE) -> 识别准确率高 | F39: =VLOOKUP(A:A,'全量进度管理'!A:L,6,FALSE) -> 中 | G39: =VLOOKUP(A:A,'全量进度管理'!A:L,8,FALSE) -> 由于教辅批阅随意，很多规律不好总结给AI，导致部分内容识别可能存在偏差 | H39: =VLOOKUP(A:A,'全量进度管理'!A:L,9,FALSE) -> 基本满足 | I39: =VLOOKUP(A:A,'全量进度管理'!A:L,10,FALSE) -> 1. 持续优化识别 2. 规范教师批阅行为
A40: 38 | D40: =VLOOKUP(A:A,'全量进度管理'!A:L,4,FALSE) -> AI自动批阅 | E40: =VLOOKUP(A:A,'全量进度管理'!A:L,5,FALSE) -> 填空题 | F40: =VLOOKUP(A:A,'全量进度管理'!A:L,6,FALSE) -> 中 | G40: =VLOOKUP(A:A,'全量进度管理'!A:L,8,FALSE) -> 无 | H40: =VLOOKUP(A:A,'全量进度管理'!A:L,9,FALSE) -> 完全不满足 | I40: =VLOOKUP(A:A,'全量进度管理'!A:L,10,FALSE) -> 优先实现英语填空题的自动批阅 | J40: =VLOOKUP(A:A,'全量进度管理'!A:L,11,FALSE) -> 46265 | K40: =VLOOKUP(A:A,'全量进度管理'!A:L,12,FALSE) -> 已排期
...

Sheet 以作业项目辐射其他群体
B1: 所属场景 | C1: 环节 | D1: 商用目标功能 | E1: 商用细分需求 | F1: 商用必备等级 | G1: 闻道作业现状 | H1: 是否满足商用目标 | I1: 后续计划 | J1: 计划完成时间 | K1: 状态
A2: 1 | B2: =VLOOKUP(A:A,'全量进度管理'!A:L,2,FALSE) -> 校本资源建设与管理 | C2: =VLOOKUP(A:A,'全量进度管理'!A:L,3,FALSE) -> 校本资源建设 | D2: =VLOOKUP(A:A,'全量进度管理'!A:L,4,FALSE) -> 校本资源建设与管理闭环 | E2: =VLOOKUP(A:A,'全量进度管理'!A:L,5,FALSE) -> 题单资源的便捷自主建设 | F2: =VLOOKUP(A:A,'全量进度管理'!A:L,6,FALSE) -> 高 | G2: =VLOOKUP(A:A,'全量进度管理'!A:L,8,FALSE) -> 支持教师自主建设题单；但欠缺一定的便捷性 | H2: =VLOOKUP(A:A,'全量进度管理'!A:L,9,FALSE) -> 基本满足 | I2: =VLOOKUP(A:A,'全量进度管理'!A:L,10,FALSE) -> 持续优化便捷性和AI识别准确性 | J2: =VLOOKUP(A:A,'全量进度管理'!A:L,11,FALSE) -> 46234 | K2: =VLOOKUP(A:A,'全量进度管理'!A:L,12,FALSE) -> 开发中
A3: 2 | E3: =VLOOKUP(A:A,'全量进度管理'!A:L,5,FALSE) -> 课件资源的便捷建设 | F3: =VLOOKUP(A:A,'全量进度管理'!A:L,6,FALSE) -> 非必须 | G3: =VLOOKUP(A:A,'全量进度管理'!A:L,8,FALSE) -> 无 | H3: =VLOOKUP(A:A,'全量进度管理'!A:L,9,FALSE) -> 完全不满足 | K3: =VLOOKUP(A:A,'全量进度管理'!A:L,12,FALSE) -> 暂不响应
A4: 3 | E4: =VLOOKUP(A:A,'全量进度管理'!A:L,5,FALSE) -> 校本资源数据看板 | F4: =VLOOKUP(A:A,'全量进度管理'!A:L,6,FALSE) -> 低 | G4: =VLOOKUP(A:A,'全量进度管理'!A:L,8,FALSE) -> 无 | H4: =VLOOKUP(A:A,'全量进度管理'!A:L,9,FALSE) -> 完全不满足 | K4: =VLOOKUP(A:A,'全量进度管理'!A:L,12,FALSE) -> 待排期
A5: 4 | E5: =VLOOKUP(A:A,'全量进度管理'!A:L,5,FALSE) -> 校本教辅的建设与使用（代为建设） | F5: 低 | G5: =VLOOKUP(A:A,'全量进度管理'!A:L,8,FALSE) -> 无 | H5: =VLOOKUP(A:A,'全量进度管理'!A:L,9,FALSE) -> 完全不满足 | I5: =VLOOKUP(A:A,'全量进度管理'!A:L,10,FALSE) -> 支持为学校建设校本教辅，且可使用 | K5: =VLOOKUP(A:A,'全量进度管理'!A:L,12,FALSE) -> 待排期
A6: 5 | B6: =VLOOKUP(A:A,'全量进度管理'!A:L,2,FALSE) -> 日常作业与练习 | C6: =VLOOKUP(A:A,'全量进度管理'!A:L,3,FALSE) -> 组卷 | D6: =VLOOKUP(A:A,'全量进度管理'!A:L,4,FALSE) -> 多来源兼容 | E6: =VLOOKUP(A:A,'全量进度管理'!A:L,5,FALSE) -> 平台内题单资源使用 | F6: =VLOOKUP(A:A,'全量进度管理'!A:L,6,FALSE) -> 高 | G6: =VLOOKUP(A:A,'全量进度管理'!A:L,8,FALSE) -> 支持用户直接使用平台内题单 | H6: =VLOOKUP(A:A,'全量进度管理'!A:L,9,FALSE) -> 完全满足
A7: 6 | E7: =VLOOKUP(A:A,'全量进度管理'!A:L,5,FALSE) -> 丰富的题库，支持题库选题组卷 | F7: =VLOOKUP(A:A,'全量进度管理'!A:L,6,FALSE) -> 高 | G7: =VLOOKUP(A:A,'全量进度管理'!A:L,8,FALSE) -> 接入学科网，支持用户从我司题库或学科网选题进行组卷 | H7: =VLOOKUP(A:A,'全量进度管理'!A:L,9,FALSE) -> 完全满足 | I7: =VLOOKUP(A:A,'全量进度管理'!A:L,10,FALSE) -> 学科网刚接入，可能在后续还有一些适配相关优化，但需使用一段时间后才能发现问题 | K7: =VLOOKUP(A:A,'全量进度管理'!A:L,12,FALSE) -> 待排期
A8: 7 | E8: =VLOOKUP(A:A,'全量进度管理'!A:L,5,FALSE) -> 自有试卷的快速使用 | F8: =VLOOKUP(A:A,'全量进度管理'!A:L,6,FALSE) -> 高 | G8: =VLOOKUP(A:A,'全量进度管理'!A:L,8,FALSE) -> 支持AI切题识别后组卷，但还无法满足“快速”的要求 | H8: =VLOOKUP(A:A,'全量进度管理'!A:L,9,FALSE) -> 基本满足 | I8: =VLOOKUP(A:A,'全量进度管理'!A:L,10,FALSE) -> 支持现成题单快速添加标记后使用，后续再完善试题内容 | K8: =VLOOKUP(A:A,'全量进度管理'!A:L,12,FALSE) -> 待排期
A9: 8 | E9: =VLOOKUP(A:A,'全量进度管理'!A:L,5,FALSE) -> 基于学情的智能组卷 | F9: =VLOOKUP(A:A,'全量进度管理'!A:L,6,FALSE) -> 低 | G9: =VLOOKUP(A:A,'全量进度管理'!A:L,8,FALSE) -> 无 | H9: =VLOOKUP(A:A,'全量进度管理'!A:L,9,FALSE) -> 完全不满足 | I9: =VLOOKUP(A:A,'全量进度管理'!A:L,10,FALSE) -> 支持教师基于学情进行智能组卷 | K9: =VLOOKUP(A:A,'全量进度管理'!A:L,12,FALSE) -> 待排期
A10: 9 | C10: =VLOOKUP(A:A,'全量进度管理'!A:L,3,FALSE) -> 生成答题卡 | D10: =VLOOKUP(A:A,'全量进度管理'!A:L,4,FALSE) -> 支持常见纸张 | E10: =VLOOKUP(A:A,'全量进度管理'!A:L,5,FALSE) -> 支持学校常用纸张 | F10: =VLOOKUP(A:A,'全量进度管理'!A:L,6,FALSE) -> 高 | G10: =VLOOKUP(A:A,'全量进度管理'!A:L,8,FALSE) -> 支持A3、A4、B4、8K常用纸张大小 | H10: =VLOOKUP(A:A,'全量进度管理'!A:L,9,FALSE) -> 完全满足
A11: 10 | E11: =VLOOKUP(A:A,'全量进度管理'!A:L,5,FALSE) -> 支持先制卡后制题 | F11: =VLOOKUP(A:A,'全量进度管理'!A:L,6,FALSE) -> 低 | G11: =VLOOKUP(A:A,'全量进度管理'!A:L,8,FALSE) -> 无 | H11: =VLOOKUP(A:A,'全量进度管理'!A:L,9,FALSE) -> 完全不满足 | I11: =VLOOKUP(A:A,'全量进度管理'!A:L,10,FALSE) -> 考试场景拓展后兼容 | K11: =VLOOKUP(A:A,'全量进度管理'!A:L,12,FALSE) -> 待排期
A12: 11 | C12: =VLOOKUP(A:A,'全量进度管理'!A:L,3,FALSE) -> 扫描 | D12: =VLOOKUP(A:A,'全量进度管理'!A:L,4,FALSE) -> 多设备兼容 | E12: =VLOOKUP(A:A,'全量进度管理'!A:L,5,FALSE) -> 支持主流品牌扫描仪的直连 | F12: =VLOOKUP(A:A,'全量进度管理'!A:L,6,FALSE) -> 中 | G12: =VLOOKUP(A:A,'全量进度管理'!A:L,8,FALSE) -> 理论上基本支持，但部分机器可能存在兼容问题，需具体型号具体观察和解决 | H12: =VLOOKUP(A:A,'全量进度管理'!A:L,9,FALSE) -> 基本满足 | I12: =VLOOKUP(A:A,'全量进度管理'!A:L,10,FALSE) -> 新增新设备使用时，提前调试，及时发现问题解决问题
A13: 12 | D13: =VLOOKUP(A:A,'全量进度管理'!A:L,4,FALSE) -> 一键式便捷扫描 | E13: =VLOOKUP(A:A,'全量进度管理'!A:L,5,FALSE) -> 扫描开始后自动进行，无额外人工动作 | F13: =VLOOKUP(A:A,'全量进度管理'!A:L,6,FALSE) -> 中 | G13: =VLOOKUP(A:A,'全量进度管理'!A:L,8,FALSE) -> 支持一键快速扫描 | H13: =VLOOKUP(A:A,'全量进度管理'!A:L,9,FALSE) -> 完全满足
A14: 13 | C14: =VLOOKUP(A:A,'全量进度管理'!A:L,3,FALSE) -> 异常处理 | D14: =VLOOKUP(A:A,'全量进度管理'!A:L,4,FALSE) -> 异常数据尽量少 | E14: =VLOOKUP(A:A,'全量进度管理'!A:L,5,FALSE) -> 有规律的异常可以系统自动处理 | F14: =VLOOKUP(A:A,'全量进度管理'!A:L,6,FALSE) -> 非必须 | G14: =VLOOKUP(A:A,'全量进度管理'!A:L,8,FALSE) -> 部分能总结出规律的异常已加入系统规则，自动处理；但仍需持续观察异常数据， | H14: =VLOOKUP(A:A,'全量进度管理'!A:L,9,FALSE) -> 完全满足
A15: 14 | D15: =VLOOKUP(A:A,'全量进度管理'!A:L,4,FALSE) -> 支持手动处理各类异常 | E15: =VLOOKUP(A:A,'全量进度管理'!A:L,5,FALSE) -> 教师能手动处理各类异常 | F15: =VLOOKUP(A:A,'全量进度管理'!A:L,6,FALSE) -> 高 | G15: =VLOOKUP(A:A,'全量进度管理'!A:L,8,FALSE) -> 支持教师、运营处理每次扫描数据的异常内容 | H15: =VLOOKUP(A:A,'全量进度管理'!A:L,9,FALSE) -> 完全满足
A16: 15 | E16: =VLOOKUP(A:A,'全量进度管理'!A:L,5,FALSE) -> 操作便捷 | F16: =VLOOKUP(A:A,'全量进度管理'!A:L,6,FALSE) -> 中 | G16: =VLOOKUP(A:A,'全量进度管理'!A:L,8,FALSE) -> 交互复杂，存在一定的优化空间 | H16: =VLOOKUP(A:A,'全量进度管理'!A:L,9,FALSE) -> 基本满足 | K16: =VLOOKUP(A:A,'全量进度管理'!A:L,12,FALSE) -> 待排期
A17: 16 | C17: =VLOOKUP(A:A,'全量进度管理'!A:L,3,FALSE) -> 识别与批改 | D17: =VLOOKUP(A:A,'全量进度管理'!A:L,4,FALSE) -> 识别准确率高 | E17: =VLOOKUP(A:A,'全量进度管理'!A:L,5,FALSE) -> AI自动识别客观题和分数准确率>99.5% | F17: =VLOOKUP(A:A,'全量进度管理'!A:L,6,FALSE) -> 高 | G17: =VLOOKUP(A:A,'全量进度管理'!A:L,8,FALSE) -> 准确率稳定在99.5%~99.8%，处于行业中上水平 | H17: =VLOOKUP(A:A,'全量进度管理'!A:L,9,FALSE) -> 完全满足
A18: 17 | D18: =VLOOKUP(A:A,'全量进度管理'!A:L,4,FALSE) -> 识别结果校验 | E18: =VLOOKUP(A:A,'全量进度管理'!A:L,5,FALSE) -> 支持快速检验采集结果的准确性 | F18: =VLOOKUP(A:A,'全量进度管理'!A:L,6,FALSE) -> 中 | G18: =VLOOKUP(A:A,'全量进度管理'!A:L,8,FALSE) -> 支持集中呈现可能识别有误的数据，支持教师手动修正 | H18: =VLOOKUP(A:A,'全量进度管理'!A:L,9,FALSE) -> 完全满足
A19: 18 | D19: =VLOOKUP(A:A,'全量进度管理'!A:L,4,FALSE) -> AI自动批阅 | E19: =VLOOKUP(A:A,'全量进度管理'!A:L,5,FALSE) -> 作文类 | F19: =VLOOKUP(A:A,'全量进度管理'!A:L,6,FALSE) -> 低 | G19: =VLOOKUP(A:A,'全量进度管理'!A:L,8,FALSE) -> 支持英语作文批阅，但是语文作文还欠缺 | H19: =VLOOKUP(A:A,'全量进度管理'!A:L,9,FALSE) -> 基本满足 | I19: =VLOOKUP(A:A,'全量进度管理'!A:L,10,FALSE) -> 支持语文作文 | K19: =VLOOKUP(A:A,'全量进度管理'!A:L,12,FALSE) -> 待排期
A20: 19 | E20: =VLOOKUP(A:A,'全量进度管理'!A:L,5,FALSE) -> 填空题 | F20: =VLOOKUP(A:A,'全量进度管理'!A:L,6,FALSE) -> 中 | G20: =VLOOKUP(A:A,'全量进度管理'!A:L,8,FALSE) -> 无 | H20: =VLOOKUP(A:A,'全量进度管理'!A:L,9,FALSE) -> 完全不满足 | I20: =VLOOKUP(A:A,'全量进度管理'!A:L,10,FALSE) -> 优先实现英语填空题的自动批阅 | J20: =VLOOKUP(A:A,'全量进度管理'!A:L,11,FALSE) -> 46265 | K20: =VLOOKUP(A:A,'全量进度管理'!A:L,12,FALSE) -> 已排期
A21: 20 | E21: =VLOOKUP(A:A,'全量进度管理'!A:L,5,FALSE) -> 主观题 | F21: =VLOOKUP(A:A,'全量进度管理'!A:L,6,FALSE) -> 中 | G21: =VLOOKUP(A:A,'全量进度管理'!A:L,8,FALSE) -> 无 | H21: =VLOOKUP(A:A,'全量进度管理'!A:L,9,FALSE) -> 完全不满足
A22: 21 | E22: =VLOOKUP(A:A,'全量进度管理'!A:L,5,FALSE) -> 留痕批阅 | F22: =VLOOKUP(A:A,'全量进度管理'!A:L,6,FALSE) -> 中 | G22: =VLOOKUP(A:A,'全量进度管理'!A:L,8,FALSE) -> 无 | H22: =VLOOKUP(A:A,'全量进度管理'!A:L,9,FALSE) -> 完全不满足
A23: 22 | D23: =VLOOKUP(A:A,'全量进度管理'!A:L,4,FALSE) -> 在线批阅 | E23: =VLOOKUP(A:A,'全量进度管理'!A:L,5,FALSE) -> 支持教师在线批阅 | F23: =VLOOKUP(A:A,'全量进度管理'!A:L,6,FALSE) -> 低 | G23: =VLOOKUP(A:A,'全量进度管理'!A:L,8,FALSE) -> 支持教师在线批阅题单 | H23: =VLOOKUP(A:A,'全量进度管理'!A:L,9,FALSE) -> 完全满足
A24: 23 | C24: =VLOOKUP(A:A,'全量进度管理'!A:L,3,FALSE) -> 数据查看与应用 | D24: =VLOOKUP(A:A,'全量进度管理'!A:L,4,FALSE) -> 教师查看数据 | E24: =VLOOKUP(A:A,'全量进度管理'!A:L,5,FALSE) -> 教师查看单次测验数据 | F24: =VLOOKUP(A:A,'全量进度管理'!A:L,6,FALSE) -> 高 | G24: =VLOOKUP(A:A,'全量进度管理'!A:L,8,FALSE) -> 支持教师查看单次测验数据 | H24: =VLOOKUP(A:A,'全量进度管理'!A:L,9,FALSE) -> 完全满足
A25: 24 | E25: =VLOOKUP(A:A,'全量进度管理'!A:L,5,FALSE) -> 教师查看阶段数据 | F25: =VLOOKUP(A:A,'全量进度管理'!A:L,6,FALSE) -> 高 | G25: =VLOOKUP(A:A,'全量进度管理'!A:L,8,FALSE) -> 支持教师查看阶段数据，但是老版本；与当前业务的融合性不够 | H25: =VLOOKUP(A:A,'全量进度管理'!A:L,9,FALSE) -> 基本满足 | I25: =VLOOKUP(A:A,'全量进度管理'!A:L,10,FALSE) -> 升级阶段学情 | K25: =VLOOKUP(A:A,'全量进度管理'!A:L,12,FALSE) -> 待排期
A26: 25 | E26: =VLOOKUP(A:A,'全量进度管理'!A:L,5,FALSE) -> 不同角色校管查看数据 | F26: =VLOOKUP(A:A,'全量进度管理'!A:L,6,FALSE) -> 高 | G26: =VLOOKUP(A:A,'全量进度管理'!A:L,8,FALSE) -> 支持不同角色查看年级数据 | H26: =VLOOKUP(A:A,'全量进度管理'!A:L,9,FALSE) -> 完全满足 | I26: =VLOOKUP(A:A,'全量进度管理'!A:L,10,FALSE) -> 由于三方系统原因，导致权限会有部分放大，但总体不影响使用；后续优化权限 | K26: =VLOOKUP(A:A,'全量进度管理'!A:L,12,FALSE) -> 待排期
A27: 26 | D27: =VLOOKUP(A:A,'全量进度管理'!A:L,4,FALSE) -> 教师讲评 | E27: =VLOOKUP(A:A,'全量进度管理'!A:L,5,FALSE) -> 支持教师基于题单进行讲评 | F27: =VLOOKUP(A:A,'全量进度管理'!A:L,6,FALSE) -> 中 | G27: =VLOOKUP(A:A,'全量进度管理'!A:L,8,FALSE) -> 支持讲评、导出讲评材料 | H27: =VLOOKUP(A:A,'全量进度管理'!A:L,9,FALSE) -> 基本满足 | I27: =VLOOKUP(A:A,'全量进度管理'!A:L,10,FALSE) -> 讲评页面书写流畅度有待优化 | K27: =VLOOKUP(A:A,'全量进度管理'!A:L,12,FALSE) -> 待排期
A28: 27 | D28: =VLOOKUP(A:A,'全量进度管理'!A:L,4,FALSE) -> 学生查看数据 | E28: =VLOOKUP(A:A,'全量进度管理'!A:L,5,FALSE) -> 学生查看单次作业数据 | F28: =VLOOKUP(A:A,'全量进度管理'!A:L,6,FALSE) -> 高 | G28: =VLOOKUP(A:A,'全量进度管理'!A:L,8,FALSE) -> 支持学生查看单次测验数据 | H28: =VLOOKUP(A:A,'全量进度管理'!A:L,9,FALSE) -> 完全满足
A29: 28 | E29: =VLOOKUP(A:A,'全量进度管理'!A:L,5,FALSE) -> 学生查看阶段学情 | F29: =VLOOKUP(A:A,'全量进度管理'!A:L,6,FALSE) -> 高 | G29: =VLOOKUP(A:A,'全量进度管理'!A:L,8,FALSE) -> 支持学生查看阶段学情 | H29: =VLOOKUP(A:A,'全量进度管理'!A:L,9,FALSE) -> 完全满足
A30: 29 | D30: =VLOOKUP(A:A,'全量进度管理'!A:L,4,FALSE) -> 学生基于学情的自习 | E30: =VLOOKUP(A:A,'全量进度管理'!A:L,5,FALSE) -> 学生自习室：基于学情查看知识讲解、进行巩固练习 | F30: =VLOOKUP(A:A,'全量进度管理'!A:L,6,FALSE) -> 低 | G30: =VLOOKUP(A:A,'全量进度管理'!A:L,8,FALSE) -> 无 | H30: =VLOOKUP(A:A,'全量进度管理'!A:L,9,FALSE) -> 完全不满足 | I30: =VLOOKUP(A:A,'全量进度管理'!A:L,10,FALSE) -> 支持学生基于学情进行知识、错题巩固 | J30: =VLOOKUP(A:A,'全量进度管理'!A:L,11,FALSE) -> 46265 | K30: =VLOOKUP(A:A,'全量进度管理'!A:L,12,FALSE) -> 已排期
A31: 30 | C31: =VLOOKUP(A:A,'全量进度管理'!A:L,3,FALSE) -> 错题的管理与运用 | D31: =VLOOKUP(A:A,'全量进度管理'!A:L,4,FALSE) -> 教师查看并应用错题 | E31: =VLOOKUP(A:A,'全量进度管理'!A:L,5,FALSE) -> 教师查看班级错题 | F31: =VLOOKUP(A:A,'全量进度管理'!A:L,6,FALSE) -> 高 | G31: =VLOOKUP(A:A,'全量进度管理'!A:L,8,FALSE) -> 支持教师查看班级错题 | H31: =VLOOKUP(A:A,'全量进度管理'!A:L,9,FALSE) -> 完全满足
A32: 31 | E32: =VLOOKUP(A:A,'全量进度管理'!A:L,5,FALSE) -> 基于班级错题的应用 | F32: =VLOOKUP(A:A,'全量进度管理'!A:L,6,FALSE) -> 中 | G32: =VLOOKUP(A:A,'全量进度管理'!A:L,8,FALSE) -> 支持教师基于错题进行组卷练习 | H32: =VLOOKUP(A:A,'全量进度管理'!A:L,9,FALSE) -> 完全满足
A33: 32 | E33: =VLOOKUP(A:A,'全量进度管理'!A:L,5,FALSE) -> 教师查看年级错题 | F33: =VLOOKUP(A:A,'全量进度管理'!A:L,6,FALSE) -> 低 | G33: =VLOOKUP(A:A,'全量进度管理'!A:L,8,FALSE) -> 无 | H33: =VLOOKUP(A:A,'全量进度管理'!A:L,9,FALSE) -> 完全不满足 | I33: =VLOOKUP(A:A,'全量进度管理'!A:L,10,FALSE) -> 支持教师查看并应用年级错题 | K33: =VLOOKUP(A:A,'全量进度管理'!A:L,12,FALSE) -> 待排期
A34: 65 | E34: =VLOOKUP(A:A,'全量进度管理'!A:L,5,FALSE) -> 基于错题自动生成学生个性化作业且可回采数据 | F34: =VLOOKUP(A:A,'全量进度管理'!A:L,6,FALSE) -> 中 | G34: =VLOOKUP(A:A,'全量进度管理'!A:L,8,FALSE) -> 可以生成统一作业，个性化作业暂不支持 | H34: =VLOOKUP(A:A,'全量进度管理'!A:L,9,FALSE) -> 基本满足
A35: 33 | D35: =VLOOKUP(A:A,'全量进度管理'!A:L,4,FALSE) -> 学生查看并管理错题 | E35: =VLOOKUP(A:A,'全量进度管理'!A:L,5,FALSE) -> 学生查看并管理个人错题 | F35: =VLOOKUP(A:A,'全量进度管理'!A:L,6,FALSE) -> 高 | G35: =VLOOKUP(A:A,'全量进度管理'!A:L,8,FALSE) -> 支持学生查看并管理个人错题 | H35: =VLOOKUP(A:A,'全量进度管理'!A:L,9,FALSE) -> 完全满足
A36: 48 | B36: =VLOOKUP(A:A,'全量进度管理'!A:L,2,FALSE) -> 多学科统考 | C36: =VLOOKUP(A:A,'全量进度管理'!A:L,3,FALSE) -> 考试管理 | D36: =VLOOKUP(A:A,'全量进度管理'!A:L,4,FALSE) -> 创建并管理考试 | E36: =VLOOKUP(A:A,'全量进度管理'!A:L,5,FALSE) -> 新增、管理多学科的考试 | F36: =VLOOKUP(A:A,'全量进度管理'!A:L,6,FALSE) -> 高 | G36: =VLOOKUP(A:A,'全量进度管理'!A:L,8,FALSE) -> 无 | H36: =VLOOKUP(A:A,'全量进度管理'!A:L,9,FALSE) -> 完全不满足 | K36: =VLOOKUP(A:A,'全量进度管理'!A:L,12,FALSE) -> 待排期
A37: 49 | E37: =VLOOKUP(A:A,'全量进度管理'!A:L,5,FALSE) -> 校内同考 | F37: =VLOOKUP(A:A,'全量进度管理'!A:L,6,FALSE) -> 高 | G37: =VLOOKUP(A:A,'全量进度管理'!A:L,8,FALSE) -> 无 | H37: =VLOOKUP(A:A,'全量进度管理'!A:L,9,FALSE) -> 完全不满足
A38: 50 | E38: =VLOOKUP(A:A,'全量进度管理'!A:L,5,FALSE) -> 跨校同考 | F38: =VLOOKUP(A:A,'全量进度管理'!A:L,6,FALSE) -> 低 | G38: =VLOOKUP(A:A,'全量进度管理'!A:L,8,FALSE) -> 无 | H38: =VLOOKUP(A:A,'全量进度管理'!A:L,9,FALSE) -> 完全不满足 | K38: =VLOOKUP(A:A,'全量进度管理'!A:L,12,FALSE) -> 待排期
A39: 51 | E39: =VLOOKUP(A:A,'全量进度管理'!A:L,5,FALSE) -> 考试进度监控 | F39: =VLOOKUP(A:A,'全量进度管理'!A:L,6,FALSE) -> 高 | H39: =VLOOKUP(A:A,'全量进度管理'!A:L,9,FALSE) -> 完全不满足
A40: 52 | C40: =VLOOKUP(A:A,'全量进度管理'!A:L,3,FALSE) -> 组卷 | D40: =VLOOKUP(A:A,'全量进度管理'!A:L,4,FALSE) -> 细目表组卷 | E40: =VLOOKUP(A:A,'全量进度管理'!A:L,5,FALSE) -> 支持细目表组卷 | F40: =VLOOKUP(A:A,'全量进度管理'!A:L,6,FALSE) -> 高 | G40: =VLOOKUP(A:A,'全量进度管理'!A:L,8,FALSE) -> 无 | H40: =VLOOKUP(A:A,'全量进度管理'!A:L,9,FALSE) -> 完全不满足 | K40: =VLOOKUP(A:A,'全量进度管理'!A:L,12,FALSE) -> 待排期
...

Sheet 全量进度管理
B2: 闻道作业商用目标地图
A4: 编号 | B4: 所属场景 | C4: 环节 | D4: 商用目标功能 | E4: 商用细分需求 | F4: 商用必备等级 | G4: 适用业务 | H4: 闻道作业现状 | I4: 是否满足商用目标 | J4: 后续计划 | K4: 计划完成时间 | L4: 状态
A5: 1 | B5: 校本资源建设与管理 | C5: 校本资源建设 | D5: 校本资源建设与管理闭环 | E5: 题单资源的便捷自主建设 | F5: 高 | G5: 直播业务,录播业务,独立项目 | H5: 支持教师自主建设题单；但欠缺一定的便捷性 | I5: 基本满足 | J5: 持续优化便捷性和AI识别准确性 | K5: 46234 | L5: 开发中
A6: 2 | E6: 课件资源的便捷建设 | F6: 非必须 | G6: 录播业务,独立项目 | H6: 无 | I6: 完全不满足 | L6: 暂不响应
A7: 3 | E7: 校本资源数据看板 | F7: 低 | G7: 直播业务,录播业务,独立项目 | H7: 无 | I7: 完全不满足 | L7: 待排期
A8: 4 | E8: 校本教辅的建设与使用（代为建设） | F8: 高 | G8: 录播业务,独立项目 | H8: 无 | I8: 完全不满足 | J8: 支持为学校建设校本教辅，且可使用 | L8: 待排期
A9: 5 | B9: 日常作业与练习 | C9: 组卷 | D9: 多来源兼容 | E9: 平台内题单资源使用 | F9: 高 | G9: 直播业务,录播业务,独立项目 | H9: 支持用户直接使用平台内题单 | I9: 完全满足
A10: 6 | E10: 丰富的题库，支持题库选题组卷 | F10: 高 | G10: 录播业务,独立项目 | H10: 接入学科网，支持用户从我司题库或学科网选题进行组卷 | I10: 完全满足 | J10: 学科网刚接入，可能在后续还有一些适配相关优化，但需使用一段时间后才能发现问题 | L10: 待排期
A11: 7 | E11: 自有试卷的快速使用 | F11: 高 | G11: 录播业务,独立项目 | H11: 支持AI切题识别后组卷，但还无法满足“快速”的要求 | I11: 基本满足 | J11: 支持现成题单快速添加标记后使用，后续再完善试题内容 | L11: 待排期
A12: 8 | E12: 基于学情的智能组卷 | F12: 低 | G12: 直播业务,录播业务,独立项目 | H12: 无 | I12: 完全不满足 | J12: 支持教师基于学情进行智能组卷 | L12: 待排期
A13: 9 | C13: 生成答题卡 | D13: 支持常见纸张 | E13: 支持学校常用纸张 | F13: 高 | G13: 直播业务,录播业务,独立项目 | H13: 支持A3、A4、B4、8K常用纸张大小 | I13: 完全满足
A14: 10 | E14: 支持先制卡后制题 | F14: 低 | G14: 直播业务,录播业务,独立项目 | H14: 无 | I14: 完全不满足 | J14: 考试场景拓展后兼容 | L14: 待排期
A15: 11 | C15: 扫描 | D15: 多设备兼容 | E15: 支持主流品牌扫描仪的直连 | F15: 中 | G15: 直播业务,录播业务,独立项目 | H15: 理论上基本支持，但部分机器可能存在兼容问题，需具体型号具体观察和解决 | I15: 基本满足 | J15: 新增新设备使用时，提前调试，及时发现问题解决问题
A16: 12 | D16: 一键式便捷扫描 | E16: 扫描开始后自动进行，无额外人工动作 | F16: 中 | G16: 直播业务,录播业务,独立项目 | H16: 支持一键快速扫描 | I16: 完全满足
A17: 13 | C17: 异常处理 | D17: 异常数据尽量少 | E17: 有规律的异常可以系统自动处理 | F17: 非必须 | G17: 直播业务,录播业务,独立项目 | H17: 部分能总结出规律的异常已加入系统规则，自动处理；但仍需持续观察异常数据， | I17: 完全满足
A18: 14 | D18: 支持手动处理各类异常 | E18: 教师能手动处理各类异常 | F18: 高 | G18: 直播业务,录播业务,独立项目 | H18: 支持教师、运营处理每次扫描数据的异常内容 | I18: 完全满足
A19: 15 | E19: 操作便捷 | F19: 中 | G19: 直播业务,录播业务,独立项目 | H19: 交互复杂，存在一定的优化空间 | I19: 基本满足 | L19: 待排期
A20: 69 | E20: 上传异常优化 | F20: 中 | G20: 直播业务,录播业务,独立项目 | I20: 完全不满足 | J20: 指定给一个已经存在作答的用户时，支持选择是合并还是覆盖
A21: 16 | C21: 识别与批改 | D21: 识别准确率高 | E21: AI自动识别客观题和分数准确率>99.5% | F21: 高 | G21: 直播业务,录播业务,独立项目 | H21: 准确率稳定在99.5%~99.8%，处于行业中上水平 | I21: 完全满足
A22: 17 | D22: 识别结果校验 | E22: 支持快速检验采集结果的准确性 | F22: 中 | G22: 直播业务,录播业务,独立项目 | H22: 支持集中呈现可能识别有误的数据，支持教师手动修正 | I22: 完全满足
A23: 18 | D23: AI自动批阅 | E23: 作文类 | F23: 低 | G23: 直播业务,录播业务,独立项目 | H23: 支持英语作文批阅，但是语文作文还欠缺 | I23: 基本满足 | J23: 支持语文作文 | L23: 待排期
A24: 19 | E24: 填空题 | F24: 中 | G24: 直播业务,录播业务,独立项目 | H24: 无 | I24: 完全不满足 | J24: 优先实现英语填空题的自动批阅 | K24: 46265 | L24: 已排期
A25: 20 | E25: 主观题 | F25: 中 | G25: 直播业务,录播业务,独立项目 | H25: 无 | I25: 完全不满足
A26: 21 | E26: 留痕批阅 | F26: 中 | G26: 直播业务,录播业务,独立项目 | H26: 无 | I26: 完全不满足
A27: 22 | D27: 在线批阅 | E27: 支持教师在线批阅 | F27: 低 | G27: 直播业务,录播业务,独立项目 | H27: 支持教师在线批阅题单 | I27: 完全满足
A28: 23 | C28: 数据查看与应用 | D28: 教师查看数据 | E28: 教师查看单次测验数据 | F28: 高 | G28: 直播业务,录播业务,独立项目 | H28: 支持教师查看单次测验数据 | I28: 完全满足
A29: 24 | E29: 教师查看阶段数据 | F29: 高 | G29: 直播业务,录播业务,独立项目 | H29: 支持教师查看阶段数据，但是老版本；与当前业务的融合性不够 | I29: 基本满足 | J29: 升级阶段学情 | L29: 待排期
A30: 25 | E30: 不同角色校管查看数据 | F30: 高 | G30: 直播业务,录播业务,独立项目 | H30: 支持不同角色查看年级数据 | I30: 完全满足 | J30: 由于三方系统原因，导致权限会有部分放大，但总体不影响使用；后续优化权限 | L30: 待排期
A31: 68 | E31: 教师支持查看全班原卷；可快速切换 | F31: 中 | G31: 直播业务,录播业务,独立项目 | H31: 支持查看单个学生原卷 | I31: 基本满足 | J31: 增设 “原卷区” ，无需逐个点击学生姓名，一键批量展示全班清晰扫描卷面，完整呈现每位学生整份答题情况，方便教师整体掌握学生答题细节。（建议：教师可选择“全卷展示”和“主观题展示”两种模式） | L31: 待排期
A32: 26 | D32: 教师讲评 | E32: 支持教师基于题单进行讲评 | F32: 中 | G32: 直播业务,录播业务,独立项目 | H32: 支持讲评、导出讲评材料 | I32: 基本满足 | J32: 讲评页面书写流畅度有待优化 | L32: 待排期
A33: 27 | D33: 学生查看数据 | E33: 学生查看单次作业数据 | F33: 高 | G33: 直播业务,录播业务,独立项目 | H33: 支持学生查看单次测验数据 | I33: 完全满足
A34: 28 | E34: 学生查看阶段学情 | F34: 高 | G34: 直播业务,录播业务,独立项目 | H34: 支持学生查看阶段学情 | I34: 完全满足
A35: 67 | E35: 支持安卓端查看各类学情数据 | F35: 低 | H35: 无 | I35: 完全不满足 | J35: 支持安卓端查看各类学情数据
A36: 29 | D36: 学生基于学情的自习 | E36: 学生自习室：基于学情查看知识讲解、进行巩固练习 | F36: 低 | G36: 直播业务,录播业务,独立项目 | H36: 无 | I36: 完全不满足 | J36: 支持学生基于学情进行知识、错题巩固 | K36: 46265 | L36: 已排期
A37: 30 | C37: 错题的管理与运用 | D37: 教师查看并应用错题 | E37: 教师查看班级错题 | F37: 高 | G37: 直播业务,录播业务,独立项目 | H37: 支持教师查看班级错题 | I37: 完全满足
A38: 31 | E38: 基于班级错题的应用 | F38: 中 | G38: 直播业务,录播业务,独立项目 | H38: 支持教师基于错题进行组卷练习 | I38: 完全满足
A39: 32 | E39: 教师查看年级错题 | F39: 低 | G39: 录播业务,独立项目 | H39: 无 | I39: 完全不满足 | J39: 支持教师查看并应用年级错题 | L39: 待排期
A40: 66 | E40: 错题再练快速生成操作 | F40: 中 | G40: 直播业务,独立项目 | H40: 支持手动选择时间生成错题再练 | I40: 基本满足 | J40: 高频错题一键生成周周清小卷（可拓展：基于假期等不同场景，生成练习卷）
A41: 65 | E41: 基于错题自动生成学生个性化作业且可回采数据 | F41: 中 | G41: 录播业务,独立项目 | H41: 可以生成统一作业，个性化作业暂不支持 | I41: 基本满足
A42: 33 | D42: 学生查看并管理错题 | E42: 学生查看并管理个人错题 | F42: 高 | G42: 直播业务,录播业务,独立项目 | H42: 支持学生查看并管理个人错题 | I42: 完全满足
...

Sheet 7中前端班使用功能梳理
A1: 七中前端班使用待完善功能梳理（9月）
A3: 应用场景 | B3: 需优化环节 | C3: 功能说明 | D3: 优先级 | E3: 计划完成时间 | F3: 状态 | G3: 备注
A4: 日常教辅作业 | B4: 数据采集 | C4: AI自动批阅（七中教师不全批全阅）-人工可核验（全学科：具体年级学科待确定） 解决方案： 1. 要求学生自己批阅 2. AI作为未批阅的试题的补充方案 | D4: P0 | G4: 全学科问题：具体年级学科待确定 主张：高一理科：英语、数学、物理、化学、生物 文科：语、数、外
B5: 单次数据查看 | C5: 前端看远端数据 | D5: P2
C6: 学生平板查看教辅数据 | D6: P0 | H6: 方案一：安卓原生 安卓：5 | I6: 方案二：内嵌H5网页 前端：6
C7: 学生平板查看学生学情 | D7: P0 | H7: 方案一：安卓原生 安卓：3 | I7: 方案二：内嵌H5网页 前端：简单适配安卓3；重新设计10
C8: 对比数据权限问题 | D8: P0 | G8: 问题：考虑前端数据分享意愿 答案：暂不考虑意愿问题；屏蔽隐私信息后共享 | H8: 前端：1
C9: 单次教辅数据UI优化 | D9: P2
B10: 阶段数据查看 | C10: 班级学情二期：阶段数据升级（含教辅等综合应用阶段数据） | D10: P1
C11: 网校阶段学情：前远端数据对比 | D11: P2
C12: 班级学情一期：教辅独立的班级学情 | D12: P0 | F12: 开发中
B13: 讲评 | C13: 支持调取学生作答（原卷？框选的作答区-有位置偏移） | D13: P0 | H13: 前端：3 后端：1
C14: 书写流畅性问题 | D14: P1
C15: 远端学生可查看前端教师的讲评视频 | D15: P1 | G15: 问题：考虑前端讲评数据分享意愿
B16: 学生自学 | C16: 学生自习室基础板（网页-学情维度的各类试题） | D16: P1
C17: 学生自习室-安卓应用 | D17: P2
C18: 课堂实录资源的整理（方案一：学本拆解、课堂记录优化） | D18: P0 | H18: 后端：6 前端：20 安卓：3
C19: 课堂实录资源的整理（方案二：同步教学栏目拓展学生端） | D19: P0 | H19: 后端：3 前端：7 安卓：不确定看原生还是网页适配
C20: 学生自习室-知识切片视频切片 | D20: P2 | G20: 问题：视频资源的分享意愿
A21: 校本资源库 | B21: 课堂资源 | C21: 课堂实录资源的整理（需确认是否9月前） | D21: P0 | F21: 待讨论 | G21: 问题：需确认是否需要给前端传达或暴露做视频切片的事项
B22: 学生应用校本资源 | C22: 校本资源在学生角色的应用 | D22: P2
A23: 补充作业/周练 | B23: 数据采集 | C23: 系统外的题单的数据采集 | D23: P2 | G23: 当前阶段： 1. 全走系统内制卷
C24: 远端直接使用前端答题卡的方式对应的数据采集 | D24: P1
B25: 多学科合并分析 | C25: 支持创建分析任务，选择各科已发布题单聚合形成一次综合性分析 | D25: P2
